Workbook

Sheet 08 Des
B3: RENCANA ANGGARAN BELANJA (RAB) BAHAN BAKU HARIAN
B4: SPPG POLRES KAB. SAMOSIR
B5: YAYASAN KEMALA BHAYANGKARI
B6: Hari : Senin, 08 Des 2025
B7: MENU : Nasi Putih, Telur Kecap Manis, Tempe, Buah Jeruk
B8: 1. Biaya Bahan Pangan
B9: NO | C9: NAMA BARANG | D9: QTY | E9: SATUAN | F9: HARGA | G9: JUMLAH | H9: NAMA SUPPLIER | I9: NAMA BANK | J9: NO REKENING | K9: TOTAL KESELURUHAN | L9: KET | M9: PARAF
B10: 1 | C10: Beras | D10: 9 | E10: Sak | F10: 155000 | G10: =F10*D10 -> 1395000 | H10: KOPERASI POLRES SAMOSIR | I10: BRI | J10: 208201012751500 (A/n AGUSTIAWAN SINAGA) | K10: =SUM(G10:G32) -> 10720250
B11: 2 | C11: Jeruk Nipis | D11: 5 | E11: Kg | F11: 21840 | G11: =F11*D11 -> 109200
B12: 3 | C12: Bawang Merah | D12: 12 | E12: Kg | F12: 42000 | G12: =F12*D12 -> 504000
B13: 4 | C13: Bawang Putih | D13: 10 | E13: Kg | F13: 42000 | G13: =F13*D13 -> 420000
B14: 5 | C14: Kemiri | D14: 10 | E14: Kg | F14: 46200 | G14: =F14*D14 -> 462000
B15: 6 | C15: Ketumbar | D15: 115 | E15: Bks | F15: 1300 | G15: =F15*D15 -> 149500
B16: 7 | C16: Minyak Goreng | D16: 40 | E16: Liter | F16: 17510 | G16: =F16*D16 -> 700400
B17: 8 | C17: Garam dolpin | D17: 15 | E17: Bks | F17: 6500 | G17: =F17*D17 -> 97500
B18: 9 | C18: Gula Merah | D18: 4 | E18: Kg | F18: 31200 | G18: =F18*D18 -> 124800
B19: 10 | C19: Serai | D19: 9 | E19: Kg | F19: 11440 | G19: =F19*D19 -> 102960
B20: 11 | C20: Lengkuas | D20: 5 | E20: Kg | F20: 11440 | G20: =F20*D20 -> 57200
B21: 12 | C21: Daun Salam | D21: 6 | E21: Ikat | F21: 2600 | G21: =F21*D21 -> 15600
B22: 13 | C22: Kunyit | D22: 2 | E22: Kg | F22: 20800 | G22: =F22*D22 -> 41600
... B26: 17 | C26: Cabe Merah | D26: 1.5 | E26: Kg | F26: 63000 | G26: =F26*D26 -> 94500
B27: 18 | C27: Tempe | D27: 145 | E27: Papan | F27: 2500 | G27: =F27*D27 -> 362500 | S27: Gas 12kg | T27: 5 | U27: tbg
B28: 19 | C28: Tahu | D28: 1.5 | E28: Papan | F28: 52500 | G28: =F28*D28 -> 78750 | S28: Gas 50kg | T28: 2 | U28: tbg
B29: 20 | C29: Timun | D29: 6 | E29: Kg | F29: 16800 | G29: =F29*D29 -> 100800 | S29: BBM | T29: 500000
B30: 21 | C30: Tomat | D30: 17 | E30: Kg | F30: 12600 | G30: =F30*D30 -> 214200 | S30: Solar | T30: 400000
B31: 22 | C31: Jeruk | D31: 120 | E31: Kg | F31: 15750 | G31: =F31*D31 -> 1890000 | S31: Sewa Mobil | T31: 1500000 | U31: Minggu 1
B32: 23 | C32: Telur | D32: 40 | E32: Papan | F32: 62400 | G32: =F32*D32 -> 2496000 | S32: Sewa Mobil | T32: 3000000 | U32: Minggu 2
B33: Total Biaya Bahan Pangan | K33: =SUM(K10) -> 10720250
B36: 2. Biaya Operasional
B37: NO. | C37: URAIAN | D37: QTY | E37: SATUAN | F37: HARGA | G37: JUMLAH | H37: NAMA SUPPLIER | I37: NAMA BANK | J37: NO REKENING | K37: TOTAL KESELURUHAN | L37: KET | M37: PARAF
B38: 1 | C38: Gas 12kg | D38: 3 | E38: Tbg | F38: 250000 | G38: =D38*F38 -> 750000 | H38: KOPERASI POLRES SAMOSIR | I38: BRI | J38: 208201012751500 (A/n AGUSTIAWAN SINAGA) | K38: =SUM(G38:G40) -> 3400000
B39: 2 | C39: Gas 50kg | D39: 2 | E39: Tbg | F39: 1200000 | G39: =D39*F39 -> 2400000
B40: 3 | C40: Bensin | D40: 25 | E40: Ltr | F40: 10000 | G40: =D40*F40 -> 250000 | N40: MITRA/awal
B41: Total Biaya Operasional | K41: =SUM(K38:K40) -> 3400000

Sheet 09 Des
B3: RENCANA ANGGARAN BELANJA (RAB) BAHAN BAKU HARIAN
B4: SPPG POLRES KAB. SAMOSIR
B5: YAYASAN KEMALA BHAYANGKARI
B6: Hari : Selasa, 09 Des 2025
B7: MENU :
B8: 1. Biaya Bahan Pangan
B9: NO | C9: NAMA BARANG | D9: QTY | E9: SATUAN | F9: HARGA | G9: JUMLAH | H9: NAMA SUPPLIER | I9: NAMA BANK | J9: NO REKENING | K9: TOTAL KESELURUHAN | L9: KET | M9: PARAF
B10: 1 | C10: Beras | D10: 8 | E10: Sak | F10: 155000 | G10: =F10*D10 -> 1240000 | H10: KOPERASI POLRES SAMOSIR | I10: BRI | J10: 208201012751500 (A/n AGUSTIAWAN SINAGA) | K10: =SUM(G10:G26) -> 11687640
B11: 2 | C11: Ayam | D11: 115 | E11: Kg | F11: 46200 | G11: =F11*D11 -> 5313000
B12: 3 | C12: Bawang Merah | D12: 13.5 | E12: Kg | F12: 44100 | G12: =F12*D12 -> 595350
B13: 4 | C13: Bawang Putih | D13: 9 | E13: Kg | F13: 42000 | G13: =F13*D13 -> 378000
B14: 5 | C14: Daun Salam | D14: 4 | E14: ikat | F14: 2600 | G14: =F14*D14 -> 10400
B15: 6 | C15: Minyak Goreng | D15: 31 | E15: Bks | F15: 17510 | G15: =F15*D15 -> 542810
B16: 7 | C16: Brokoli | D16: 65 | E16: kg | F16: 19950 | G16: =F16*D16 -> 1296750
B17: 8 | C17: Gula Pasir | D17: 1 | E17: kg | F17: 18720 | G17: =F17*D17 -> 18720
B18: 9 | C18: Cabe Merah | D18: 1 | E18: Kg | F18: 68250 | G18: =F18*D18 -> 68250
B19: 10 | C19: Tahu | D19: 6 | E19: papan | F19: 52500 | G19: =F19*D19 -> 315000
B20: 11 | C20: Tepung Serba guna | D20: 3 | E20: kg | F20: 43260 | G20: =F20*D20 -> 129780
B21: 12 | C21: Tepung Beras | D21: 1 | E21: kg | F21: 19570 | G21: =F21*D21 -> 19570
B22: 13 | C22: Kaldu Bubuk | D22: 1 | E22: bks | F22: 10500 | G22: =F22*D22 -> 10500
... B26: 17 | C26: Pisang | D26: 93 | E26: sisir | F26: 15750 | G26: =F26*D26 -> 1464750
B27: Total Biaya Bahan Pangan | K27: =SUM(K10) -> 11687640
B30: 2. Biaya Operasional
B31: NO. | C31: URAIAN | D31: QTY | E31: SATUAN | F31: HARGA | G31: JUMLAH | H31: NAMA SUPPLIER | I31: NAMA BANK | J31: NO REKENING | K31: TOTAL KESELURUHAN | L31: KET | M31: PARAF
B32: 1 | C32: Gas 12kg | D32: 0 | E32: Tbg | F32: 250000 | G32: =D32*F32 -> 0
B33: 2 | C33: Gas 50kg | D33: 0 | E33: Tbg | F33: 1300000 | G33: =D33*F33 -> 0
B34: 3 | C34: Bensin | D34: 0 | E34: Ltr | F34: 250000 | G34: =D34*F34 -> 0
B35: Total Biaya Operasional | K35: =SUM(K32:K34) -> 0
B116: RENCANA ANGGARAN BELANJA (RAB) BAHAN BAKU HARIAN
B117: SPPG POLRES KAB. SAMOSIR
B118: YAYASAN KEMALA BHAYANGKARI
B119: Hari : Selasa, 09 Des 2025
B120: MENU :
B121: NO | C121: URAIAN | D121: QTY | E121: SATUAN | F121: HARGA | G121: JUMLAH | H121: KETERANGAN
B122: 1 | C122: Beras | D122: 8 | E122: Sak | F122: 155000 | G122: =F122*D122 -> 1240000 | H122: 1 karung isi 10kg
B123: 2 | C123: Ayam | D123: 115 | E123: Kg | F123: 46200 | G123: =F123*D123 -> 5313000
B124: 3 | C124: Bawang Merah | D124: 13.5 | E124: Kg | F124: 44100 | G124: =F124*D124 -> 595350
B125: 4 | C125: Bawang Putih | D125: 9 | E125: Kg | F125: 42000 | G125: =F125*D125 -> 378000
B126: 5 | C126: Daun Salam | D126: 4 | E126: ikat | F126: 2600 | G126: =F126*D126 -> 10400
B127: 6 | C127: Minyak Goreng | D127: 31 | E127: Bks | F127: 17510 | G127: =F127*D127 -> 542810
...

Sheet 10 Des
B3: RENCANA ANGGARAN BELANJA (RAB) BAHAN BAKU HARIAN
B4: SPPG POLRES KAB. SAMOSIR
B5: YAYASAN KEMALA BHAYANGKARI
B6: Hari : Rabu, 10 Des 2025
B7: MENU :
B8: 1. Biaya Bahan Pangan
B9: NO | C9: NAMA BARANG | D9: QTY | E9: SATUAN | F9: HARGA | G9: JUMLAH | H9: NAMA SUPPLIER | I9: NAMA BANK | J9: NO REKENING | K9: TOTAL KESELURUHAN | L9: KET | M9: PARAF
B10: 1 | C10: Beras(Matahari) | D10: 8 | E10: Sak | F10: 169950 | G10: =F10*D10 -> 1359600 | H10: KOPERASI POLRES SAMOSIR | I10: BRI | J10: 208201012751500 (A/n AGUSTIAWAN SINAGA) | K10: =SUM(G10:G25) -> 10685385
B11: 2 | C11: Ikan lele | D11: 162 | E11: Kg | F11: 30500 | G11: =F11*D11 -> 4941000
B12: 3 | C12: Jeruk Nipis | D12: 5 | E12: kg | F12: 21840 | G12: =F12*D12 -> 109200
B13: 4 | C13: Garam dolphin(500gr) | D13: 10 | E13: bks | F13: 10500 | G13: =F13*D13 -> 105000
B14: 5 | C14: Minyak Goreng | D14: 30 | E14: Ltr | F14: 17510 | G14: =F14*D14 -> 525300
B15: 6 | C15: Bawang merah | D15: 5 | E15: Kg | F15: 44100 | G15: =F15*D15 -> 220500
B16: 7 | C16: Bawang Putih | D16: 3 | E16: kg | F16: 42000 | G16: =F16*D16 -> 126000
B17: 8 | C17: Cabe Merah | D17: 3.5 | E17: kg | F17: 68250 | G17: =F17*D17 -> 238875
B18: 9 | C18: Cabai rawit | D18: 1 | E18: Kg | F18: 53550 | G18: =F18*D18 -> 53550
B19: 10 | C19: Tomat | D19: 17 | E19: Kg | F19: 12600 | G19: =F19*D19 -> 214200
B20: 11 | C20: Tempe | D20: 140 | E20: papan | F20: 2500 | G20: =F20*D20 -> 350000
B21: 12 | C21: Sawi putih | D21: 86 | E21: kg | F21: 10500 | G21: =F21*D21 -> 903000
B22: 13 | C22: Saos tiram | D22: 2 | E22: kg | F22: 82400 | G22: =F22*D22 -> 164800
... B24: 15 | C24: Semangka | D24: 100 | E24: Kg | F24: 13650 | G24: =F24*D24 -> 1365000
G25: =F25*D25 -> 0
B26: Total Biaya Bahan Pangan | K26: =SUM(K10) -> 10685385
B29: 2. Biaya Operasional
B30: NO. | C30: URAIAN | D30: QTY | E30: SATUAN | F30: HARGA | G30: JUMLAH | H30: NAMA SUPPLIER | I30: NAMA BANK | J30: NO REKENING | K30: TOTAL KESELURUHAN | L30: KET | M30: PARAF
B31: 1 | C31: Gas 12kg | D31: 0 | E31: Tbg | F31: 250000 | G31: =D31*F31 -> 0
B32: 2 | C32: Gas 50kg | D32: 0 | E32: Tbg | F32: 1500000 | G32: =D32*F32 -> 0
B33: 3 | C33: Bensin | D33: 25 | E33: Ltr | F33: 10000 | G33: =D33*F33 -> 250000 | H33: KOPERASI POLRES SAMOSIR | I33: BRI | J33: 208201012751500 (A/n AGUSTIAWAN SINAGA) | K33: =G33 -> 250000
B34: 4 | C34: Fotocopy Absensi | D34: 102 | E34: Lbr | F34: 300 | G34: 31000 | H34: GRACIA FOTOCOPY | I34: BRI | J34: 5379 0101 9452 539 (A/n BARITA SITUMORANG) | K34: =SUM(G34:G35) -> 81000
B35: 5 | C35: Tali Rapia | D35: 1 | E35: Ball | F35: 50000 | G35: =D35*F35 -> 50000 | H35: UD TUMPAL SITANGGANG
B36: 6 | C36: Mama Lime 680ml | D36: 5 | E36: bks | F36: 13000 | G36: =D36*F36 -> 65000 | H36: WARUNG GANDA | I36: MANDIRI | J36: 1050021198654 (A/n PASULINA SITORUS) | K36: =G36 -> 65000
B38: Total Biaya Operasional | K38: =SUM(K31:K37) -> 396000

Sheet 11 Des
B3: RENCANA ANGGARAN BELANJA (RAB) BAHAN BAKU HARIAN
B4: SPPG POLRES KAB. SAMOSIR
B5: YAYASAN KEMALA BHAYANGKARI
B6: Hari : Kamis, 11 Des 2025
B7: MENU :
B8: 1. Biaya Bahan Pangan
B9: NO | C9: NAMA BARANG | D9: QTY | E9: SATUAN | F9: HARGA | G9: JUMLAH | H9: NAMA SUPPLIER | I9: NAMA BANK | J9: NO REKENING | K9: TOTAL KESELURUHAN | L9: KET | M9: PARAF
B10: 1 | C10: Beras | D10: 9 | E10: Sak | F10: 160000 | G10: =F10*D10 -> 1440000 | H10: KOPERASI POLRES SAMOSIR | I10: BRI | J10: 208201012751500 (A/n AGUSTIAWAN SINAGA) | K10: =SUM(G10:G23) -> 10199030
B11: 2 | C11: Telur | D11: 40 | E11: Papan | F11: 64480 | G11: =F11*D11 -> 2579200
B12: 3 | C12: Kecap manis(700gr) | D12: 17 | E12: sachet | F12: 28840 | G12: =F12*D12 -> 490280
B13: 4 | C13: Bawang Merah | D13: 12 | E13: kg | F13: 44100 | G13: =F13*D13 -> 529200
B14: 5 | C14: Bawang Putih | D14: 10 | E14: kg | F14: 42000 | G14: =F14*D14 -> 420000
B15: 6 | C15: Daun bawang | D15: 6 | E15: kg | F15: 23100 | G15: =F15*D15 -> 138600
B16: 7 | C16: Minyak goreng | D16: 35 | E16: liter | F16: 18720 | G16: =F16*D16 -> 655200
B17: 8 | C17: Garam | D17: 10 | E17: bks | F17: 10500 | G17: =F17*D17 -> 105000
B18: 9 | C18: Tahu | D18: 11 | E18: papan | F18: 52500 | G18: =F18*D18 -> 577500
B19: 10 | C19: Labu siam | D19: 90 | E19: kg | F19: 12600 | G19: =F19*D19 -> 1134000
B20: 11 | C20: Cabe merah | D20: 3 | E20: Kg | F20: 68250 | G20: =F20*D20 -> 204750
B21: 12 | C21: Daun Salam | D21: 5.5 | E21: ikat | F21: 2600 | G21: =F21*D21 -> 14300
B22: 13 | C22: Jeruk | D22: 120 | E22: Kg | F22: 15750 | G22: =F22*D22 -> 1890000
B23: 14 | C23: Kaldu bubuk masako | D23: 2 | E23: bks | F23: 10500 | G23: =F23*D23 -> 21000
B24: 15 | C24: Jeruk | D24: 4.5 | E24: kg | F24: 13000 | G24: =F24*D24 -> 58500 | H24: WARUNG JORDAN | I24: MANDIRI | J24: 1050021198654 (A/n PASULINA SITORUS) | K24: =SUM(G24:G25) -> 70500
B25: 16 | C25: Nenas | D25: 1 | E25: bh | F25: 12000 | G25: =F25*D25 -> 12000 | H25: WARUNG THEODORA
B26: 17 | C26: Saos Tiram 270ml | D26: 2 | E26: botol | F26: 23500 | G26: =F26*D26 -> 47000 | H26: ALFAMIDI | I26: BRI | J26: 5379 0101 9452 539 (A/n BARITA SITUMORANG) | K26: =G26 -> 47000
B28: Total Biaya Bahan Pangan | K28: =SUM(K10:K27) -> 10316530
B31: 2. Biaya Operasional
B32: NO. | C32: URAIAN | D32: QTY | E32: SATUAN | F32: HARGA | G32: JUMLAH | H32: NAMA SUPPLIER | I32: NAMA BANK | J32: NO REKENING | K32: TOTAL KESELURUHAN | L32: KET | M32: PARAF
B33: 1 | C33: Gas 12kg | D33: 0 | E33: Tbg | F33: 250000 | G33: =D33*F33 -> 0
B34: 2 | C34: Gas 50kg | D34: 0 | E34: Tbg | F34: 1500000 | G34: =D34*F34 -> 0
B35: 3 | C35: Bensin | D35: 0 | E35: Ltr | F35: 250000 | G35: =D35*F35 -> 0
B36: Total Biaya Operasional | K36: =SUM(K33:K35) -> 0

Sheet 12 Des
B3: RENCANA ANGGARAN BELANJA (RAB) BAHAN BAKU HARIAN
B4: SPPG POLRES KAB. SAMOSIR
B5: YAYASAN KEMALA BHAYANGKARI
B6: Hari : Jumat, 12 Des 2025
B7: MENU :
B8: 1. Biaya Bahan Pangan
B9: NO | C9: NAMA BARANG | D9: QTY | E9: SATUAN | F9: HARGA | G9: JUMLAH | H9: NAMA SUPPLIER | I9: NAMA BANK | J9: NO REKENING | K9: TOTAL KESELURUHAN | L9: KET | M9: PARAF
B10: 1 | C10: Beras | D10: 7 | E10: kg | F10: 161200 | G10: =F10*D10 -> 1128400 | H10: KOPERASI POLRES SAMOSIR | I10: BRI | J10: 208201012751500 (A/n AGUSTIAWAN SINAGA) | K10: =SUM(G10:G22) -> 10679135
B11: 2 | C11: Nila | D11: 135 | E11: Kg | F11: 37800 | G11: =F11*D11 -> 5103000
B12: 3 | C12: Cabe Merah | D12: 3.5 | E12: kg | F12: 68500 | G12: =F12*D12 -> 239750
B13: 4 | C13: Cabe rawit | D13: 2 | E13: bks | F13: 65100 | G13: =F13*D13 -> 130200
B14: 5 | C14: Minyak goreng | D14: 40 | E14: Ltr | F14: 17510 | G14: =F14*D14 -> 700400
B15: 6 | C15: Garam kasar | D15: 3 | E15: bks | F15: 3500 | G15: =F15*D15 -> 10500
B16: 7 | C16: Tempe | D16: 140 | E16: ons | F16: 2500 | G16: =F16*D16 -> 350000
B17: 8 | C17: Tomat | D17: 17 | E17: kg | F17: 8500 | G17: =F17*D17 -> 144500
B18: 9 | C18: Jeruk nipis | D18: 4 | E18: kg | F18: 21840 | G18: =F18*D18 -> 87360
B19: 10 | C19: Bunga kol | D19: 61.5 | E19: kg | F19: 26250 | G19: =F19*D19 -> 1614375
B20: 11 | C20: Daun salam | D20: 4 | E20: ikat | F20: 2600 | G20: =F20*D20 -> 10400
B21: 12 | C21: Salak | D21: 85 | E21: kg | F21: 13650 | G21: =F21*D21 -> 1160250
G22: =F22*D22 -> 0
B23: Total Biaya Bahan Pangan | K23: =SUM(K10) -> 10679135
B26: 2. Biaya Operasional
B27: NO. | C27: URAIAN | D27: QTY | E27: SATUAN | F27: HARGA | G27: JUMLAH | H27: NAMA SUPPLIER | I27: NAMA BANK | J27: NO REKENING | K27: TOTAL KESELURUHAN | L27: KET | M27: PARAF
B28: 1 | C28: Gas 12kg | D28: 0 | E28: Tbg | F28: 250000 | G28: =D28*F28 -> 0
B29: 2 | C29: Gas 50kg | D29: 0 | E29: Tbg | F29: 1500000 | G29: =D29*F29 -> 0
B30: 3 | C30: Bensin | D30: 1 | E30: Ltr | F30: 250000 | G30: =D30*F30 -> 250000
B31: 4 | C31: Tali Rapia k | D31: 1 | E31: ball | F31: 40000 | G31: =D31*F31 -> 40000 | I31: BRI | J31: 5379 0101 9452 539 (A/n BARITA SITUMORANG) | K31: =G31 -> 40000
B32: 5 | C32: Plastik asoy b | D32: 2 | E32: bks | F32: 40000 | G32: =D32*F32 -> 80000 | H32: UD. TUMPAL SITANGGANG | I32: MANDIRI | J32: 1050021198654 (A/n PASULINA SITORUS) | K32: =SUM(G32:G33) -> 90000
B33: 6 | C33: Plastik asoy k | D33: 2 | E33: bks | F33: 5000 | G33: =D33*F33 -> 10000
B34: Total Biaya Operasional | K34: =SUM(K28:K33) -> 130000

Sheet 13 Des
B3: RENCANA ANGGARAN BELANJA (RAB) BAHAN BAKU HARIAN
B4: SPPG POLRES KAB. SAMOSIR
B5: YAYASAN KEMALA BHAYANGKARI
B6: Hari : Sabtu, 13 Des 2025
B7: MENU :
B8: 1. Biaya Bahan Pangan
B9: NO | C9: NAMA BARANG | D9: QTY | E9: SATUAN | F9: HARGA | G9: JUMLAH | H9: NAMA SUPPLIER | I9: NAMA BANK | J9: NO REKENING | K9: TOTAL KESELURUHAN | L9: KET | M9: PARAF
B10: 1 | C10: Roti | D10: 1140 | E10: bks | F10: 2100 | G10: =F10*D10 -> 2394000 | H10: KOPERASI POLRES SAMOSIR | I10: BRI | J10: 208201012751500 (A/n AGUSTIAWAN SINAGA) | K10: =SUM(G10:G13) -> 8432240
B11: 2 | C11: Telur | D11: 38 | E11: papan | F11: 64480 | G11: =F11*D11 -> 2450240
B12: 3 | C12: Kacang Tanah/Kacang rondam | D12: 5 | E12: kaleng | F12: 499200 | G12: =F12*D12 -> 2496000
B13: 4 | C13: Salak | D13: 80 | E13: kg | F13: 13650 | G13: =F13*D13 -> 1092000
B14: Total Biaya Bahan Pangan | K14: =SUM(K10) -> 8432240
B19: 2. Biaya Operasional
B20: NO. | C20: URAIAN | D20: QTY | E20: SATUAN | F20: HARGA | G20: JUMLAH | H20: NAMA SUPPLIER | I20: NAMA BANK | J20: NO REKENING | K20: TOTAL KESELURUHAN | L20: KET | M20: PARAF
B21: 1 | C21: Gas 12kg | D21: 0 | E21: Tbg | F21: 250000 | G21: =D21*F21 -> 0 | H21: KOPERASI POLRES SAMOSIR | I21: BRI | J21: 208201012751500 (A/n AGUSTIAWAN SINAGA) | K21: =SUM(G21:G26) -> 542810
B22: 2 | C22: Gas 50kg | D22: 0 | E22: Tbg | F22: 1500000 | G22: =D22*F22 -> 0
B23: 3 | C23: So klin lantai 800ml | D23: 5 | E23: btl | F23: 17510 | G23: =D23*F23 -> 87550
B24: 4 | C24: Cling pembersih kaca | D24: 2 | E24: btl | F24: 16480 | G24: =D24*F24 -> 32960
B25: 5 | C25: Plastik opp | D25: 11 | E25: bks | F25: 10300 | G25: =D25*F25 -> 113300
B26: 6 | C26: Mama Lemon 680ml | D26: 30 | E26: bks | F26: 10300 | G26: =D26*F26 -> 309000
B27: 7 | C27: Bensin | D27: 30 | E27: Ltr | F27: 10000 | G27: =D27*F27 -> 300000 | H27: PERTAMINA | I27: MANDIRI | J27: 1050021198654 (A/n PASULINA SITORUS) | K27: =G27 -> 300000
B28: Total Biaya Operasional | K28: =SUM(K21:K27) -> 842810

Sheet 15 Des
B3: RENCANA ANGGARAN BELANJA (RAB) BAHAN BAKU HARIAN
B4: SPPG POLRES KAB. SAMOSIR
B5: YAYASAN KEMALA BHAYANGKARI
B6: Hari : Senin, 15 Des 2025
B7: MENU :
B8: 1. Biaya Bahan Pangan
B9: NO | C9: NAMA BARANG | D9: QTY | E9: SATUAN | F9: HARGA | G9: JUMLAH | H9: NAMA SUPPLIER | I9: NAMA BANK | J9: NO REKENING | K9: TOTAL KESELURUHAN | L9: KET | M9: PARAF
B10: 1 | C10: Beras '@10kg | D10: 13 | E10: Sak | F10: 175000 | G10: =F10*D10 -> 2275000 | H10: KOPERASI POLRES SAMOSIR | I10: BRI | J10: 208201012751500 (A/n AGUSTIAWAN SINAGA) | K10: =SUM(G10:G28) -> 17803910
B11: 2 | C11: Ayam | D11: 180 | E11: Kg | F11: 48760 | G11: =F11*D11 -> 8776800
B12: 3 | C12: Cabe merah | D12: 6 | E12: kg | F12: 71000 | G12: =F12*D12 -> 426000
B13: 4 | C13: Saos tiram | D13: 12 | E13: botol | F13: 11330 | G13: =F13*D13 -> 135960
B14: 5 | C14: Bawang Merah | D14: 5 | E14: kg | F14: 50400 | G14: =F14*D14 -> 252000
B15: 6 | C15: Bawang putih | D15: 3 | E15: kg | F15: 42000 | G15: =F15*D15 -> 126000
B16: 7 | C16: Minyak goreng | D16: 47 | E16: Ltr | F16: 24500 | G16: =F16*D16 -> 1151500
B17: 8 | C17: Garam kasar | D17: 3 | E17: bks | F17: 6000 | G17: =F17*D17 -> 18000
B18: 9 | C18: Tahu | D18: 14 | E18: papan | F18: 52500 | G18: =F18*D18 -> 735000
B19: 10 | C19: Daun bawang | D19: 2 | E19: ons | F19: 4200 | G19: =F19*D19 -> 8400
B20: 11 | C20: Santan kental | D20: 50 | E20: sachet | F20: 7500 | G20: =F20*D20 -> 375000
B21: 12 | C21: Kunyit | D21: 2 | E21: kg | F21: 28000 | G21: =F21*D21 -> 56000
B22: 13 | C22: Sawi putih | D22: 115 | E22: Kg | F22: 10200 | G22: =F22*D22 -> 1173000
... B27: 18 | C27: Duku | D27: 115 | E27: kg | F27: 18750 | G27: =F27*D27 -> 2156250
B28: 19 | C28: Garam kasar | D28: 1 | E28: pack | F28: 25000 | G28: =F28*D28 -> 25000 | H28: WARUNG JORDAN | I28: MANDIRI | J28: 1050021198654 (A/n PASULINA SITORUS) | K28: =G28 -> 25000
B29: Total Biaya Bahan Pangan | K29: =SUM(K10:K28) -> 17828910
B32: 2. Biaya Operasional
B33: NO. | C33: URAIAN | D33: QTY | E33: SATUAN | F33: HARGA | G33: JUMLAH | H33: NAMA SUPPLIER | I33: NAMA BANK | J33: NO REKENING | K33: TOTAL KESELURUHAN | L33: KET | M33: PARAF
B34: 1 | C34: Gas 12kg | D34: 0 | E34: Tbg | F34: 250000 | G34: =D34*F34 -> 0 | H34: KOPERASI POLRES SAMOSIR | I34: BRI | J34: 208201012751500 (A/n AGUSTIAWAN SINAGA) | K34: =SUM(G34:G37) -> 31500
B35: 2 | C35: Gas 50kg | D35: 0 | E35: Tbg | F35: 1500000 | G35: =D35*F35 -> 0
B36: 3 | C36: Bensin | D36: 0 | E36: Tbg | F36: 10000 | G36: =D36*F36 -> 0
B37: 4 | C37: Tali Rapia k | D37: 3 | E37: Glg | F37: 10500 | G37: =D37*F37 -> 31500
B38: 5 | C38: Tali Rapia | D38: 5 | E38: Glg | F38: 12000 | G38: =D38*F38 -> 60000 | H38: UD. AUREL SITANGGANG | I38: BRI | J38: 5379 0101 9452 539 (A/n BARITA SITUMORANG) | K38: =SUM(G38:G39) -> 112000
B39: 6 | C39: Plastik Warna | D39: 4 | E39: Glg | F39: 13000 | G39: =D39*F39 -> 52000
B40: 7 | C40: Tali Rapia | D40: 4 | E40: Glg | F40: 7000 | G40: =D40*F40 -> 28000 | H40: WARUNG JORDAN | I40: MANDIRI | J40: 1050021198654 (A/n PASULINA SITORUS) | K40: =G40 -> 28000
B42: Total Biaya Operasional | K42: =SUM(K34:K40) -> 171500

Sheet 16 Des
B3: RENCANA ANGGARAN BELANJA (RAB) BAHAN BAKU HARIAN
B4: SPPG POLRES KAB. SAMOSIR
B5: YAYASAN KEMALA BHAYANGKARI
B6: Hari : 16 Des 2025
B7: MENU :
B8: 1. Biaya Bahan Pangan
B9: NO | C9: NAMA BARANG | D9: QTY | E9: SATUAN | F9: HARGA | G9: JUMLAH | H9: NAMA SUPPLIER | I9: NAMA BANK | J9: NO REKENING | K9: TOTAL KESELURUHAN | L9: KET | M9: PARAF
B10: 1 | C10: Beras | D10: 14 | E10: Sak | F10: 175000 | G10: =F10*D10 -> 2450000 | H10: KOPERASI POLRES SAMOSIR | I10: BRI | J10: 208201012751500 (A/n AGUSTIAWAN SINAGA) | K10: =SUM(G10:G23) -> 17619700
B11: 2 | C11: Mujahir | D11: 175 | E11: kg | F11: 40600 | G11: =F11*D11 -> 7105000
B12: 3 | C12: Cabe merah | D12: 7 | E12: kg | F12: 71500 | G12: =F12*D12 -> 500500
B13: 4 | C13: Cabe rawit | D13: 5 | E13: kg | F13: 79800 | G13: =F13*D13 -> 399000
B14: 5 | C14: Bawang Merah | D14: 9 | E14: kg | F14: 50400 | G14: =F14*D14 -> 453600
B15: 6 | C15: Bawang putih | D15: 4 | E15: kg | F15: 42000 | G15: =F15*D15 -> 168000
B16: 7 | C16: Minyak Goreng | D16: 55 | E16: liter | F16: 24500 | G16: =F16*D16 -> 1347500
B17: 8 | C17: Tempe | D17: 240 | E17: papan | F17: 2750 | G17: =F17*D17 -> 660000
B18: 9 | C18: Tomat | D18: 28 | E18: kg | F18: 12000 | G18: =F18*D18 -> 336000
B19: 10 | C19: Labu siam | D19: 145 | E19: kg | F19: 13000 | G19: =F19*D19 -> 1885000
B20: 11 | C20: Salak | D20: 95 | E20: Kg | F20: 16300 | G20: =F20*D20 -> 1548500
B21: 12 | C21: Telor | D21: 11 | E21: papan | F21: 65000 | G21: =F21*D21 -> 715000 | H21: UD. MONA | K21: =G21 -> 715000
B22: 13 | C22: Garam | D22: 6 | E22: bks | F22: 8600 | G22: =F22*D22 -> 51600 | H22: ALFAMIDI | I22: MANDIRI | J22: 1050021198654 (A/n PASULINA SITORUS) | K22: =G22 -> 51600
G23: =F23*D23 -> 0
B24: Total Biaya Bahan Pangan | K24: =SUM(K10:K23) -> 18386300
B27: 2. Biaya Operasional
B28: NO. | C28: URAIAN | D28: QTY | E28: SATUAN | F28: HARGA | G28: JUMLAH | H28: NAMA SUPPLIER | I28: NAMA BANK | J28: NO REKENING | K28: TOTAL KESELURUHAN | L28: KET | M28: PARAF
B29: 1 | C29: Gas 12kg | D29: 0 | E29: Tbg | F29: 250000 | G29: =D29*F29 -> 0 | I29: BRI | J29: 208201012751500 (A/n AGUSTIAWAN SINAGA) | K29: =SUM(G29:G31) -> 25750
B30: 2 | C30: Gas 50kg | D30: 0 | E30: Tbg | F30: 1500000 | G30: =D30*F30 -> 0
B31: 3 | C31: Porstex kamar mandi | D31: 1 | E31: botol | F31: 25750 | G31: =D31*F31 -> 25750
B32: 4 | C32: Bensin Mobil BK1180QM | D32: 25 | E32: Ltr | F32: 10000 | G32: =D32*F32 -> 250000 | H32: PERTAMINA | I32: MANDIRI | J32: 1050021198654 (A/n PASULINA SITORUS) | K32: =G32 -> 250000
B33: Total Biaya Operasional | K33: =SUM(K29:K32) -> 275750

Sheet 17 Des
B3: RENCANA ANGGARAN BELANJA (RAB) BAHAN BAKU HARIAN
B4: SPPG POLRES KAB. SAMOSIR
B5: YAYASAN KEMALA BHAYANGKARI
B6: Hari : Rabu, 17 Des 2025
B7: MENU :
B8: 1. Biaya Bahan Pangan
B9: NO | C9: NAMA BARANG | D9: QTY | E9: SATUAN | F9: HARGA | G9: JUMLAH | H9: NAMA SUPPLIER | I9: NAMA BANK | J9: NO REKENING | K9: TOTAL KESELURUHAN | L9: KET | M9: PARAF
B10: 1 | C10: Beras | D10: 14 | E10: Sak | F10: 160000 | G10: =F10*D10 -> 2240000 | H10: KOPERASI POLRES SAMOSIR | I10: BRI | J10: 208201012751500 (A/n AGUSTIAWAN SINAGA) | K10: =SUM(G10:G26) -> 18642090
B11: 2 | C11: Ayam | D11: 174 | E11: kg | F11: 48760 | G11: =F11*D11 -> 8484240
B12: 3 | C12: Cabe merah | D12: 7 | E12: kg | F12: 68250 | G12: =F12*D12 -> 477750
B13: 4 | C13: Cabe rawit | D13: 5 | E13: kg | F13: 79800 | G13: =F13*D13 -> 399000
B14: 5 | C14: Bawang Merah | D14: 9 | E14: kg | F14: 50400 | G14: =F14*D14 -> 453600
B15: 6 | C15: Bawang putih | D15: 5 | E15: kg | F15: 42000 | G15: =F15*D15 -> 210000
B16: 7 | C16: Santan kental | D16: 65 | E16: sachet | F16: 7500 | G16: =F16*D16 -> 487500
B17: 8 | C17: Minyak Goreng | D17: 55 | E17: liter | F17: 24500 | G17: =F17*D17 -> 1347500
B18: 9 | C18: Garam kasar | D18: 1 | E18: pak | F18: 25000 | G18: =F18*D18 -> 25000
B19: 10 | C19: Tahu | D19: 15 | E19: papan | F19: 52500 | G19: =F19*D19 -> 787500
B20: 11 | C20: Kunyit | D20: 3 | E20: kg | F20: 28000 | G20: =F20*D20 -> 84000
B21: 12 | C21: Lengkuas | D21: 3 | E21: Kg | F21: 14500 | G21: =F21*D21 -> 43500
B22: 13 | C22: Jahe | D22: 5 | E22: kg | F22: 35600 | G22: =F22*D22 -> 178000
... B25: 16 | C25: Semangka | D25: 115 | E25: kg | F25: 15500 | G25: =F25*D25 -> 1782500
B27: Total Biaya Bahan Pangan | K27: =SUM(K10) -> 18642090
B30: 2. Biaya Operasional
B31: NO. | C31: URAIAN | D31: QTY | E31: SATUAN | F31: HARGA | G31: JUMLAH | H31: NAMA SUPPLIER | I31: NAMA BANK | J31: NO REKENING | K31: TOTAL KESELURUHAN | L31: KET | M31: PARAF
B32: 1 | C32: Gas 12kg | D32: 0 | E32: Tbg | F32: 250000 | G32: =D32*F32 -> 0 | H32: KOPERASI POLRES SAMOSIR | I32: BRI | J32: 208201012751500 (A/n AGUSTIAWAN SINAGA) | K32: =SUM(G32:G35) -> 103000
B33: 2 | C33: Gas 50kg | D33: 0 | E33: Tbg | F33: 1500000 | G33: =D33*F33 -> 0 | N33: BLM MASUK PENCAICAN PERIODE 1
B34: 3 | C34: Tali Rapia k | D34: 1 | E34: glg | F34: 10300 | G34: =D34*F34 -> 10300
B35: 4 | C35: Tali Rapia isi 12 glg | D35: 1 | E35: ball | F35: 92700 | G35: =D35*F35 -> 92700
B36: 5 | C36: Bensin | D36: 15 | E36: Ltr | F36: 10000 | G36: =D36*F36 -> 150000 | H36: PERTAMINA | I36: BRI | J36: 5379 0101 9452 539 (A/n BARITA SITUMORANG) | K36: =SUM(G32:G36) -> 253000
B37: Total Biaya Operasional | K37: =SUM(K32:K36) -> 356000

Sheet 18 Des
B3: RENCANA ANGGARAN BELANJA (RAB) BAHAN BAKU HARIAN
B4: SPPG POLRES KAB. SAMOSIR
B5: YAYASAN KEMALA BHAYANGKARI
B6: Hari : Kamis, 18 Des 2025
B7: MENU :
B8: 1. Biaya Bahan Pangan
B9: NO | C9: NAMA BARANG | D9: QTY | E9: SATUAN | F9: HARGA | G9: JUMLAH | H9: NAMA SUPPLIER | I9: NAMA BANK | J9: NO REKENING | K9: TOTAL KESELURUHAN | L9: KET | M9: PARAF
B10: 1 | C10: Beras | D10: 13 | E10: Sak | F10: 175000 | G10: =F10*D10 -> 2275000 | H10: KOPERASI POLRES SAMOSIR | I10: BRI | J10: 208201012751500 (A/n AGUSTIAWAN SINAGA) | K10: =SUM(G10:G21) -> 16087300
B11: 2 | C11: Nila | D11: 170 | E11: kg | F11: 40600 | G11: =F11*D11 -> 6902000
B12: 3 | C12: Saos tiram | D12: 12 | E12: botol | F12: 12360 | G12: =F12*D12 -> 148320
B13: 4 | C13: Minyak Goreng | D13: 55 | E13: liter | F13: 24500 | G13: =F13*D13 -> 1347500
B14: 5 | C14: Garam kasar | D14: 4 | E14: pak | F14: 29120 | G14: =F14*D14 -> 116480
B15: 6 | C15: Tempe | D15: 240 | E15: papan | F15: 2750 | G15: =F15*D15 -> 660000
B16: 7 | C16: Tomat | D16: 28 | E16: kg | F16: 12000 | G16: =F16*D16 -> 336000
B17: 8 | C17: Kacang panjang | D17: 97 | E17: kg | F17: 22500 | G17: =F17*D17 -> 2182500
B18: 9 | C18: Jahe | D18: 3 | E18: kg | F18: 31500 | G18: =F18*D18 -> 94500
B19: 10 | C19: Rambutan | D19: 125 | E19: ikat | F19: 15700 | G19: =F19*D19 -> 1962500
B20: 11 | C20: Tepung terigu | D20: 5 | E20: kg | F20: 12500 | G20: =F20*D20 -> 62500
B22: Total Biaya Bahan Pangan | K22: =SUM(K10) -> 16087300
B25: 2. Biaya Operasional
B26: NO. | C26: URAIAN | D26: QTY | E26: SATUAN | F26: HARGA | G26: JUMLAH | H26: NAMA SUPPLIER | I26: NAMA BANK | J26: NO REKENING | K26: TOTAL KESELURUHAN | L26: KET | M26: PARAF
B27: 1 | C27: Gas 12kg | D27: 0 | E27: Tbg | F27: 250000 | G27: =D27*F27 -> 0
B28: 2 | C28: Gas 50kg | D28: 2 | E28: Tbg | F28: 1500000 | G28: =D28*F28 -> 3000000
B29: 3 | C29: Bensin | D29: 0 | E29: Ltr | F29: 10000 | G29: =D29*F29 -> 0
B30: 4 | C30: Air isi ulang | D30: 9 | E30: galon | F30: 7000 | G30: =D30*F30 -> 63000 | H30: RM ARMI | I30: MANDIRI | J30: 1050021198654 (A/n PASULINA SITORUS) | K30: =SUM(G30) -> 63000
B31: Total Biaya Operasional | K31: =SUM(K27:K30) -> 63000

Sheet 19 Des
B3: RENCANA ANGGARAN BELANJA (RAB) BAHAN BAKU HARIAN
B4: SPPG POLRES KAB. SAMOSIR
B5: YAYASAN KEMALA BHAYANGKARI
B6: Hari : Jumat, 19 Des 2025
B7: MENU :
B8: 1. Biaya Bahan Pangan
B9: NO | C9: NAMA BARANG | D9: QTY | E9: SATUAN | F9: HARGA | G9: JUMLAH | H9: NAMA SUPPLIER | I9: NAMA BANK | J9: NO REKENING | K9: TOTAL KESELURUHAN | L9: KET | M9: PARAF
B10: 1 | C10: Telur | D10: 87 | E10: papan | F10: 65000 | G10: =D10*F10 -> 5655000 | H10: KOPERASI POLRES SAMOSIR | I10: BRI | J10: 208201012751500 (A/n AGUSTIAWAN SINAGA) | K10: =SUM(G10:G13) -> 13786000
B11: 2 | C11: Jeruk | D11: 130 | E11: kg | F11: 15700 | G11: =F11*D11 -> 2041000
B12: 3 | C12: Roti | D12: 1740 | E12: bks | F12: 3500 | G12: =F12*D12 -> 6090000
B14: Total Biaya Bahan Pangan | K14: =SUM(K10) -> 13786000
B17: 2. Biaya Operasional
B18: NO. | C18: URAIAN | D18: QTY | E18: SATUAN | F18: HARGA | G18: JUMLAH | H18: NAMA SUPPLIER | I18: NAMA BANK | J18: NO REKENING | K18: TOTAL KESELURUHAN | L18: KET | M18: PARAF
B19: 1 | C19: Gas 12kg | D19: 0 | E19: Tbg | F19: 250000 | G19: =D19*F19 -> 0
B20: 2 | C20: Gas 50kg | D20: 0 | E20: Tbg | F20: 1500000 | G20: =D20*F20 -> 0
B21: 3 | C21: Bensin | D21: 20 | E21: Ltr | F21: 10000 | G21: =D21*F21 -> 200000 | N21: Yayasan
B22: 4
B23: 5
B24: 6
B25: Total Biaya Operasional | K25: =SUM(K19:K24) -> 0

Sheet 20 Des
B3: RENCANA ANGGARAN BELANJA (RAB) BAHAN BAKU HARIAN
B4: SPPG POLRES KAB. SAMOSIR
B5: YAYASAN KEMALA BHAYANGKARI
B6: Hari : Sabtu, 20 Des 2025
B7: MENU :
B8: 1. Biaya Bahan Pangan
B9: NO | C9: NAMA BARANG | D9: QTY | E9: SATUAN | F9: HARGA | G9: JUMLAH | H9: NAMA SUPPLIER | I9: NAMA BANK | J9: NO REKENING | K9: TOTAL KESELURUHAN | L9: KET | M9: PARAF
B10: 1 | C10: Telur | D10: 87 | E10: papan | F10: 65000 | G10: =F10*D10 -> 5655000 | H10: KOPERASI POLRES SAMOSIR | I10: BRI | J10: 208201012751500 (A/n AGUSTIAWAN SINAGA) | K10: =SUM(G10:G13) -> 13786000
B11: 2 | C11: Jeruk | D11: 130 | E11: kg | F11: 15700 | G11: =F11*D11 -> 2041000
B12: 3 | C12: Roti | D12: 1740 | E12: bks | F12: 3500 | G12: =F12*D12 -> 6090000
G13: =F13*D13 -> 0
B14: Total Biaya Bahan Pangan | K14: =SUM(K10) -> 13786000
B17: 2. Biaya Operasional
B18: NO. | C18: URAIAN | D18: QTY | E18: SATUAN | F18: HARGA | G18: JUMLAH | H18: NAMA SUPPLIER | I18: NAMA BANK | J18: NO REKENING | K18: TOTAL KESELURUHAN | L18: KET | M18: PARAF
B19: 1 | C19: Gas 12kg | D19: 0 | E19: Tbg | F19: 250000 | G19: =D19*F19 -> 0
B20: 2 | C20: Gas 50kg | D20: 0 | E20: Tbg | F20: 1500000 | G20: =D20*F20 -> 0
B21: 3 | C21: Bensin | D21: 0 | E21: Ltr | F21: 10000 | G21: =D21*F21 -> 0
B22: 4 | C22: Wifi | D22: 1 | E22: Bln | F22: 295000 | G22: =D22*F22 -> 295000 | K22: =G22 -> 295000
B23: 5 | G23: =D23*F23 -> 0
B24: 6 | G24: =D24*F24 -> 0
B25: Total Biaya Operasional | K25: =SUM(K19:K24) -> 295000

Sheet SUMMARY
B5: TGL | C5: BAHAN BAKU | D5: OPERASIONAL | E5: INSENTIF | F5: OPERASIONAL YG AKAN DIBYR | G5: OPERASIONAL BLM MASUK REKAP
B6: 45999 | C6: ='08 Des'!K33 -> 10720250 | D6: ='08 Des'!K41 -> 3400000 | E6: 6000000 | F6: 47020000 | G6: Gaji Relawan | K6: MITRA
B7: 46000 | C7: ='09 Des'!K27 -> 11687640 | D7: ='09 Des'!K35 -> 0 | E7: 6000000 | G7: Air / tgl 1 | K7: Gas 12kg | L7: 5 | M7: tbg
B8: 46001 | C8: ='10 Des'!K26 -> 10685385 | D8: ='10 Des'!K38 -> 396000 | E8: 6000000 | G8: Listrik/ tgl 8 | K8: Gas 50kg | L8: 2 | M8: tbg
B9: 46002 | C9: ='11 Des'!K28 -> 10316530 | D9: 0 | E9: 6000000 | F9: 860000 | G9: BPJS / tgl 22 | K9: BBM | L9: 500000
B10: 46003 | C10: ='12 Des'!K23 -> 10679135 | D10: ='12 Des'!K34 -> 130000 | E10: 6000000 | F10: 298000 | G10: Wifi/ tgl 20 + admin 3rb | H10: Bg Agus | K10: Solar | L10: 400000
B11: 46004 | C11: ='13 Des'!K14 -> 8432240 | D11: ='13 Des'!K28 -> 842810 | E11: 6000000 | G11: Insentif pic guru | K11: Sewa Mobil | L11: 1500000 | M11: Minggu 1
B12: 46006 | C12: ='15 Des'!K29 -> 17828910 | D12: ='15 Des'!K42 -> 171500 | E12: 6000000 | F12: 4500000 | G12: Sewa Mobil /250rb/hr/mobil | K12: Sewa Mobil | L12: 3000000 | M12: Minggu 2
B13: 46007 | C13: ='16 Des'!K24 -> 18386300 | D13: ='16 Des'!K33 -> 275750 | E13: 6000000 | G13: Solar 400rb
B14: 46008 | C14: ='17 Des'!K27 -> 18642090 | D14: ='17 Des'!K37 -> 356000 | E14: 6000000
B15: 46009 | C15: ='18 Des'!K22 -> 16087300 | D15: ='18 Des'!K31 -> 63000 | E15: 6000000
B16: 46010 | C16: ='19 Des'!K14 -> 13786000 | D16: ='19 Des'!K25 -> 0 | E16: 6000000
B17: 46011 | C17: ='20 Des'!K14 -> 13786000 | D17: ='20 Des'!K25 -> 295000 | E17: 6000000
C18: =SUM(C6:C17) -> 161037780 | D18: =SUM(D6:D17) -> 5930060 | E18: =SUM(E6:E17) -> 72000000 | F18: =SUM(F6:F17) -> 52678000
D21: =SUM(C18:F18) -> 291645840
B24: BAHAN BAKU DARI SPPG
B25: TGL | C25: BAHAN BAKU | D25: OPERASIONAL
B26: 45999 | C26: ='09 Des'!K46 -> 0 | D26: ='10 Des'!K56 -> 0
B27: 46000 | C27: ='09 Des'!K47 -> 0 | D27: ='09 Des'!K55 -> 0
B28: 46001 | C28: =SUM('10 Des'!K34:K36) -> 146000 | D28: =SUM('10 Des'!K34:K36) -> 146000
B29: 46002 | C29: =SUM('11 Des'!K24:K26) -> 117500 | D29: 0
B30: 46003 | C30: ='13 Des'!K33 -> 0 | D30: =SUM('12 Des'!K31:K33) -> 130000
B31: 46004 | C31: ='13 Des'!K34 -> 0 | D31: =SUM('13 Des'!K27) -> 300000
B32: 46006 | C32: =SUM('15 Des'!K28) -> 25000 | D32: =SUM('15 Des'!K38:K40) -> 140000
B33: 46007 | C33: =SUM('16 Des'!K21:K22) -> 766600 | D33: =SUM('16 Des'!K32) -> 250000
B34: 46008 | C34: ='17 Des'!K47 -> 0 | D34: =SUM('17 Des'!K36) -> 253000
B35: 46009 | C35: ='18 Des'!K42 -> 0 | D35: =SUM('18 Des'!K30) -> 63000
B36: 46010 | C36: ='19 Des'!K34 -> 0
B37: 46011 | C37: ='20 Des'!K34 -> 0 | D37: ='20 Des'!K45 -> 0
C38: =SUM(C26:C37) -> 1055100 | D38: =SUM(D26:D37) -> 1282000
